Workbook
Name city_list: INDEX(Country_Table[],,MATCH('User Inputs'!Selection,'User Inputs'!Country_List,0))
Name city_list: INDEX(Country_Table[],,MATCH(Selection,Country_List,0))
Name city_list2: INDEX(Country_Table[],1,'User Inputs'!col_num) : INDEX('List Selections'!#REF!, COUNTA('User Inputs'!entire_col), 'User Inputs'!col_num)
Name city_list2: INDEX(Country_Table[],1,col_num) : INDEX('List Selections'!#REF!, COUNTA(entire_col), col_num)
Name col_num: MATCH('User Inputs'!Selection,'User Inputs'!Country_List,0)
Name col_num: MATCH(Selection,Country_List,0)
Name Country_List: Country_Table[#Headers]
Name Country_List: Country_Table[#Headers]
Name entire_col: INDEX('User Inputs'!city_list,,'User Inputs'!col_num)
Name entire_col: INDEX(city_list,,col_num)
Name Selection: 'User Inputs'!$D1
Name Selection: 'Inputs (detail)'!$D1

Sheet User Inputs
B2: User Inputs
B4: Legend
B5: Boxes that are this color require a user input
B7: Global Inputs
C9: Unit | D9: Country | E9: City | F9: Team Size | G9: Mode of Travel | H9: Hotel Star
B10: Claimant | C10: - | D10: Germany | E10: Munich | F10: 3 | G10: Plane (Business) | H10: 3
B11: Claimant Counsel | C11: - | D11: Spain | E11: Madrid | F11: 4 | G11: Rail | H11: 5
B12: Claimant Expert | C12: - | D12: United Kingdom | E12: London | F12: 2 | G12: Plane (Business) | H12: 4
B13: Respondent | C13: - | D13: Italy | E13: Milan | F13: 2 | G13: Rail | H13: 5
B14: Respondent Counsel | C14: - | D14: Germany | E14: Frankfurt | F14: 5 | G14: Rail | H14: 3
B15: Respondent Expert | C15: - | D15: United Kingdom | E15: London | F15: 3 | G15: Plane (Business) | H15: 5
B16: Arbitrator 1 | C16: - | D16: United Kingdom | E16: London | F16: 1 | G16: Plane (Economy) | H16: 4
B17: Arbitrator 2 | C17: - | D17: France | E17: Paris | F17: 1 | G17: Plane (Economy) | H17: 4
B18: Arbitrator 3 | C18: - | D18: Poland | E18: Warsaw | F18: 1 | G18: Plane (Business) | H18: 5
B19: Hearing (if in person) | C19: - | D19: France | E19: Paris
B20: How many submissions in total? | C20: # | D20: 4
B21: Was the hearing virtual? | C21: - | D21: No
B22: Duration of arbitration | C22: months | D22: 24
B23: Duration of hearing | C23: days | D23: 5
B25: Claimant in-person meetings
D27: Claimant location | E27: Counsel location | F27: Expert location
B28: In-person meetings | C28: # | D28: 2 | E28: 0 | F28: 1
B29: Total duration of in-person meetings | C29: days | D29: 3 | E29: 0 | F29: 1
B30: Average number of attendees from Claimant | C30: # | D30: 3 | E30: 3 | F30: 2
B31: Average number of attendees from Counsel | C31: # | D31: 2 | E31: 4 | F31: 1
B32: Average number of attendees from Expert | C32: # | D32: 1 | E32: 1 | F32: 2
B34: Respondent in-person meetings
D36: Respondent location | E36: Counsel location | F36: Expert location
B37: In-person meetings | C37: # | D37: 1 | E37: 4 | F37: 1
B38: Total duration of in-person meetings | C38: days | D38: 5 | E38: 18 | F38: 5
B39: Average number of attendees from Respondent | C39: # | D39: 2 | E39: 2 | F39: 2
B40: Average number of attendees from Counsel | C40: # | D40: 3 | E40: 5 | F40: 2
B41: Average number of attendees from Expert | C41: # | D41: 2 | E41: 2 | F41: 3

Sheet Inputs (detail)
B2: User Inputs
B4: Legend
B5: Boxes that are this color require a user input
B7: Global Inputs
C8: Unit | D8: Country | E8: City | F8: Mode of Travel | G8: Hotel Type
B9: Locations
B10: Claimant | C10: country | D10: ='User Inputs'!D10 -> Germany | E10: ='User Inputs'!E10 -> Munich
B11: Claimant Counsel | C11: country | D11: ='User Inputs'!D11 -> Spain | E11: ='User Inputs'!E11 -> Madrid
B12: Claimant Expert | C12: country | D12: ='User Inputs'!D12 -> United Kingdom | E12: ='User Inputs'!E12 -> London
B13: Respondent | C13: country | D13: ='User Inputs'!D13 -> Italy | E13: ='User Inputs'!E13 -> Milan
B14: Respondent Counsel | C14: country | D14: ='User Inputs'!D14 -> Germany | E14: ='User Inputs'!E14 -> Frankfurt
B15: Respondent Expert | C15: country | D15: ='User Inputs'!D15 -> United Kingdom | E15: ='User Inputs'!E15 -> London
B16: Hearing | C16: country | D16: ='User Inputs'!D19 -> France | E16: ='User Inputs'!E19 -> Paris
B17: Arbitrator 1 | C17: country | D17: ='User Inputs'!D16 -> United Kingdom | E17: ='User Inputs'!E16 -> London | F17: ='User Inputs'!G16 -> Plane (Economy) | G17: ='User Inputs'!H16 -> 4
B18: Arbitrator 2 | C18: country | D18: ='User Inputs'!D17 -> France | E18: ='User Inputs'!E17 -> Paris | F18: ='User Inputs'!G17 -> Plane (Economy) | G18: ='User Inputs'!H17 -> 4
B19: Arbitrator 3 | C19: country | D19: ='User Inputs'!D18 -> Poland | E19: ='User Inputs'!E18 -> Warsaw | F19: ='User Inputs'!G18 -> Plane (Business) | G19: ='User Inputs'!H18 -> 5
B21: Durations
B22: Hearing length | C22: days | D22: ='User Inputs'!D23 -> 5
B23: Was the hearing virtual? | C23: - | D23: ='User Inputs'!D21 -> No
B26: Phase-specific Inputs | E26: Notes
B28: Claimant
B29: Claimant team size | C29: count | D29: ='User Inputs'!$F10 -> 3
B30: Claimant's Counsel team size | C30: count | D30: ='User Inputs'!$F11 -> 4
B31: Claimant's Expert team size | C31: count | D31: ='User Inputs'!$F12 -> 2
B33: Number of printed memos/reports | C33: count | D33: ='User Inputs'!D20/2*3*SUM(D29:D31)/2 -> 27 | E33: 3 printed memos/reports per phase, with printouts for half all team members
B34: Number of pages per memo | C34: pages | D34: 100 | E34: Assumed average of 100 pages per memo/report based on CGA insights
B35: Printed at Claimant location | C35: % | D35: =IFERROR(D29/SUM(D$29:D$31),0) -> 0.33333333 | E35: Assuming the quantity printed is based on the number of people at each location
B36: Printed at Counsel location | C36: % | D36: =IFERROR(D30/SUM(D$29:D$31),0) -> 0.44444444 | E36: Assuming the quantity printed is based on the number of people at each location
B37: Printed at Expert location | C37: % | D37: =IFERROR(D31/SUM(D$29:D$31),0) -> 0.22222222 | E37: Assuming the quantity printed is based on the number of people at each location
B38: Printed at Hearing location | C38: % | D38: 0 | E38: Assuming the quantity printed is based on the number of people at each location
B39: Number of emails | C39: emails | D39: =100*SUM(D29:D31) -> 900
B40: Notebooks Used | C40: count | D40: =1*SUM(D29:D31) -> 9 | E40: Assumed one per person
B41: Pen and Pencil Used | C41: count | D41: =2*SUM(D29:D31) -> 18 | E41: Assumed two per person
B42: Cup Usage | C42: count | D42: ='User Inputs'!D29*SUM('User Inputs'!D30:D32)+'User Inputs'!E29*SUM('User Inputs'!E30:E32)+'User Inputs'!F29*SUM('User Inputs'!F30:F32) -> 23 | E42: Assumed one per person per in-person meeting
B44: Data Generated | C44: Gigabytes | D44: ='User Inputs'!D20/2*5 -> 10 | E44: Assumed 5GB per phase/submission
B46: Number of in-person meetings at Claimant location | C46: count | D46: ='User Inputs'!D28 -> 2
B47: Total duration of meetings at Claimant location | C47: days | D47: ='User Inputs'!D29 -> 3
B48: Hotel type | C48: - | D48: =ROUND(AVERAGE('User Inputs'!H11:H12),0) -> 5
B49: Counsel team mode of transport | C49: - | D49: ='User Inputs'!G11 -> Rail
B50: Expert team mode of transport | C50: - | D50: ='User Inputs'!G12 -> Plane (Business)
...

Sheet Outputs
B2: Results
B4: Claimant
B5: Scope 2 | D5: kgCO2e
B6: Printing & Email | D6: =SUM('Emissions Calcs'!C11:C15) -> 3.6040776
B7: Computer Use | D7: ='Emissions Calcs'!C16 -> 208.8
B8: Total Scope 2 | D8: =SUM(D6:D7) -> 212.40408
B10: Scope 3 | D10: kgCO2e
B11: Printing & Email | D11: =SUM('Emissions Calcs'!C30:C34) -> 3.6366987
B12: Data Storage | D12: ='Emissions Calcs'!C57 -> 35.073255
B13: Computer Manufacturing and Operating | D13: ='Emissions Calcs'!C35 -> 1183.2
B14: Travel | D14: =SUM('Emissions Calcs'!C41:C42,'Emissions Calcs'!C45:C46,'Emissions Calcs'!C49:C50,'Emissions Calcs'!C53:C55) -> 5859.0953
B15: Hotel Stays | D15: =SUM('Emissions Calcs'!C40,'Emissions Calcs'!C44,'Emissions Calcs'!C48,'Emissions Calcs'!C52) -> 1427.2799
B16: Material Use | D16: =SUM('Emissions Calcs'!C36:C38) -> 4.4649542
B17: Total Scope 3 | D17: =SUM(D11:D16) -> 8512.7501
B19: Total Claimant | D19: =SUM(D17,D8) -> 8725.1542
B21: Respondent
B22: Scope 2 | D22: kgCO2e
B23: Printing & Email | D23: =SUM('Emissions Calcs'!C19:C23) -> 4.0585688
B24: Computer Use | D24: ='Emissions Calcs'!C24 -> 232
B25: Total Scope 2 | D25: =SUM(D23:D24) -> 236.05857
B27: Scope 3 | D27: kgCO2e
B28: Printing & Email | D28: =SUM('Emissions Calcs'!C60:C64) -> 4.0585688
B29: Data Storage | D29: ='Emissions Calcs'!C87 -> 42.145079
B30: Computer Manufacturing and Operating | D30: ='Emissions Calcs'!C65 -> 1314.6667
B31: Travel | D31: =SUM('Emissions Calcs'!C71:C72,'Emissions Calcs'!C75:C76,'Emissions Calcs'!C79:C80,'Emissions Calcs'!C83:C85) -> 23833.925
B32: Hotel Stays | D32: =SUM('Emissions Calcs'!C70,'Emissions Calcs'!C74,'Emissions Calcs'!C78,'Emissions Calcs'!C82) -> 7883.5214
B33: Material Use | D33: =SUM('Emissions Calcs'!C66:C68) -> 6.6332603
B34: Total Scope 3 | D34: =SUM(D28:D33) -> 33084.95
B36: Total Respondent | D36: =SUM(D34,D25) -> 33321.008
B38: Arbitrators
B39: Scope 2
B40: Printing & Email | D40: =SUM('Emissions Calcs'!C99:C101) -> 0.015660947
B41: Computer Use | D41: =SUM('Emissions Calcs'!C107) -> 69.6
B42: Total Scope 2 | D42: =SUM(D40:D41) -> 69.615661
B44: Scope 3
B45: Printing & Email | D45: =SUM('Emissions Calcs'!C103:C105) -> 0.0071883745
B46: Data Storage | D46: =SUM('Emissions Calcs'!C111:C113) -> 43.52003
B47: Computer Manufacturing and Operating | D47: =SUM('Emissions Calcs'!C109) -> 394.4
B48: Travel to Hearing | D48: =SUM('Emissions Calcs'!C91:C93) -> 446.47165
B49: Hotel Stays at Hearing Location | D49: =SUM('Emissions Calcs'!C95:C97) -> 174.37231
...

Sheet Assumptions
B2: Model Assumptions
B4: Assumption | D4: Units | E4: Quantity | F4: Notes | G4: Source
B6: Printing
B7: Copy per person involved | D7: item | E7: 1 | F7: Assumed
B8: Electricity consumption when printing | D8: Wh | E8: 400 | G8: https://energyusecalculator.com/electricity_printer.htm
B9: Printed pages per minute (ppm) | D9: ppm | E9: 1000 | F9: Assumed
B10: Printed pages per hour | D10: pages | E10: 60000 | F10: Assumed
B11: Electricity consumption when printing | D11: kWh/page | E11: =E8/E10/1000 -> 6.6666667e-06
B12: WTT - UK | D12: kgCO2e/kWh | E12: 0.459 | F12: Used with EI electricity generation by country to calculate scope 3 emissions | G12: UK Government GHG Conversion Factors for Company Reporting
B14: Computer Use
B15: Laptop + screen at office + screen at home annual per person | D15: kgCO2e | E15: 928 | G15: https://www.it.ox.ac.uk/article/environment-and-it
B16: Use, in months | D16: Months | E16: 72 | F16: Assumed
B17: Laptop + screen at office + screen at home monthly per person assigned at this case | D17: kgCO2e | E17: =(E15/72)*E18 -> 6.4444444 | G17: Assuming 50% of each person's computer time is dedicated to this case
B18: Computer use time assigned on this case | E18: 0.5
B19: Computer Use Scope 2 (%) | E19: 0.15 | G19: https://www.it.ox.ac.uk/article/environment-and-it
B20: Computer Use Scope 3 (%) | E20: 0.85 | G20: https://www.it.ox.ac.uk/article/environment-and-it
B21: Emissions of one email | D21: kgCO2 | E21: 0.004 | G21: https://www.biospheresustainable.com/en/blog/65/digital-carbon-footprint-what-is-involved-in-sending-an-email
B22: Data storage (active) | D22: kWh/GB | E22: 5 | G22: https://stanfordmag.org/contents/carbon-and-the-cloud
B23: Data storage (archive) | D23: kWh/GB/year | E23: 0.002 | F23: Assumed for tape storage of cold data
B25: Materials Use
B26: GHG emissions per paper cup | D26: kgCO2e | E26: 0.0081 | F26: When disposed following European rules | G26: https://www.huhtamaki.com/globalassets/global/highlights/responsibility/taking-a-closer-look-at-paper-cups-for-coffee.pdf
B27: Paper production per tonne | D27: kgCO2e | E27: 910.4781 | G27: UK Government GHG Conversion Factors for Company Reporting
B28: Average plastics production per tonne | D28: kgCO2e | E28: 3102.4485 | G28: UK Government GHG Conversion Factors for Company Reporting
B30: Travel
B31: Car (non-electric) | D31: kgCO2e/km (per passenger) | E31: 0.15090452 | F31: Average size car, average of petrol, diesel and mild hybrid | G31: UK Government GHG Conversion Factors for Company Reporting
B32: Car (electric) | D32: kgCO2e/km (per passenger) | E32: 0.054796442 | F32: Average size car, full electric | G32: UK Government GHG Conversion Factors for Company Reporting
B33: Plane (Economy) short haul | D33: kgCO2e/km (per passenger) | E33: 0.18286935 | G33: UK Government GHG Conversion Factors for Company Reporting
B34: Plane (Business) short haul | D34: kgCO2e/km (per passenger) | E34: 0.27430288 | G34: UK Government GHG Conversion Factors for Company Reporting
B35: Plane (Economy) long haul | D35: kgCO2e/km (per passenger) | E35: 0.13464333 | G35: UK Government GHG Conversion Factors for Company Reporting
B36: Plane (Business) long haul | D36: kgCO2e/km (per passenger) | E36: 0.39044321 | G36: UK Government GHG Conversion Factors for Company Reporting
B37: Long haul threshold | D37: km | E37: 3000 | F37: Assumed
B38: Rail | D38: kgCO2e/km (per passenger) | E38: 0.019961021 | F38: Average of national and international rail | G38: UK Government GHG Conversion Factors for Company Reporting

Sheet Helpers >

Sheet Transport Calcs
B2: Intermediate Transport Calculations
B4: Notes
B6: No values on this sheet should be edited. All values should be linked back to "User Inputs".
B7: This sheet calculated emissions per single trip. Total transport emissions are calculated in the next tab.
C9: Plane (Economy) | D9: Plane (Economy) | E9: Plane (Economy) | F9: Plane (Economy) | G9: Plane (Business) | H9: Plane (Business) | I9: Plane (Business) | J9: Plane (Business) | K9: Rail | L9: Rail | M9: Rail | N9: Rail | O9: Car (non-electric) | P9: Car (non-electric) | Q9: Car (non-electric) | R9: Car (non-electric) | S9: Car (electric) | T9: Car (electric) | U9: Car (electric) | V9: Car (electric)
C10: Claimant | D10: Claimant Counsel | E10: Claimant Expert | F10: Hearing | G10: Claimant | H10: Claimant Counsel | I10: Claimant Expert | J10: Hearing | K10: Claimant | L10: Claimant Counsel | M10: Claimant Expert | N10: Hearing | O10: Claimant | P10: Claimant Counsel | Q10: Claimant Expert | R10: Hearing | S10: Claimant | T10: Claimant Counsel | U10: Claimant Expert | V10: Hearing
B11: Claimant | C11: =IF($B11=C$10,0,INDEX('Travel Matrix'!$D$7:$GT$205,MATCH(INDEX('Inputs (detail)'!$E$10:$E$16,MATCH($B11,'Inputs (detail)'!$B$10:$B$16,0)),'Travel Matrix'!$C$7:$C$205,0),MATCH(INDEX('Inputs (detail)'!$E$10:$E$16,MATCH(C$10,'Inputs (detail)'!$B$10:$B$16,0)),'Travel Matrix'!$D$6:$GT$6,0))*IF(INDEX('Travel Matrix'!$D$7:$GT$205,MATCH(INDEX('Inputs (detail)'!$E$10:$E$16,MATCH($B11,'Inputs (detail)'!$B$10:$B$16,0)),'Travel Matrix'!$C$7:$C$205,0),MATCH(INDEX('Inputs (detail)'!$E$10:$E$16,MATCH(C$10,'Inputs (detail)'!$B$10:$B$16,0)),'Travel Matrix'!$D$6:$GT$6,0))>Assumptions!$E$37,IF(C$9="Plane (Economy)",Assumptions!$E$35,Assumptions!$E$36),IF(C$9="Plane (Economy)",Assumptions!$E$33,Assumptions!$E$34))) -> 0 | D11: =IF($B11=D$10,0,INDEX('Travel Matrix'!$D$7:$GT$205,MATCH(INDEX('Inputs (detail)'!$E$10:$E$16,MATCH($B11,'Inputs (detail)'!$B$10:$B$16,0)),'Travel Matrix'!$C$7:$C$205,0),MATCH(INDEX('Inputs (detail)'!$E$10:$E$16,MATCH(D$10,'Inputs (detail)'!$B$10:$B$16,0)),'Travel Matrix'!$D$6:$GT$6,0))*IF(INDEX('Travel Matrix'!$D$7:$GT$205,MATCH(INDEX('Inputs (detail)'!$E$10:$E$16,MATCH($B11,'Inputs (detail)'!$B$10:$B$16,0)),'Travel Matrix'!$C$7:$C$205,0),MATCH(INDEX('Inputs (detail)'!$E$10:$E$16,MATCH(D$10,'Inputs (detail)'!$B$10:$B$16,0)),'Travel Matrix'!$D$6:$GT$6,0))>Assumptions!$E$37,IF(D$9="Plane (Economy)",Assumptions!$E$35,Assumptions!$E$36),IF(D$9="Plane (Economy)",Assumptions!$E$33,Assumptions!$E$34))) -> 270.76574 | E11: =IF($B11=E$10,0,INDEX('Travel Matrix'!$D$7:$GT$205,MATCH(INDEX('Inputs (detail)'!$E$10:$E$16,MATCH($B11,'Inputs (detail)'!$B$10:$B$16,0)),'Travel Matrix'!$C$7:$C$205,0),MATCH(INDEX('Inputs (detail)'!$E$10:$E$16,MATCH(E$10,'Inputs (detail)'!$B$10:$B$16,0)),'Travel Matrix'!$D$6:$GT$6,0))*IF(INDEX('Travel Matrix'!$D$7:$GT$205,MATCH(INDEX('Inputs (detail)'!$E$10:$E$16,MATCH($B11,'Inputs (detail)'!$B$10:$B$16,0)),'Travel Matrix'!$C$7:$C$205,0),MATCH(INDEX('Inputs (detail)'!$E$10:$E$16,MATCH(E$10,'Inputs (detail)'!$B$10:$B$16,0)),'Travel Matrix'!$D$6:$GT$6,0))>Assumptions!$E$37,IF(E$9="Plane (Economy)",Assumptions!$E$35,Assumptions!$E$36),IF(E$9="Plane (Economy)",Assumptions!$E$33,Assumptions!$E$34))) -> 166.07063 | F11: =IF($B11=F$10,0,INDEX('Travel Matrix'!$D$7:$GT$205,MATCH(INDEX('Inputs (detail)'!$E$10:$E$16,MATCH($B11,'Inputs (detail)'!$B$10:$B$16,0)),'Travel Matrix'!$C$7:$C$205,0),MATCH(INDEX('Inputs (detail)'!$E$10:$E$16,MATCH(F$10,'Inputs (detail)'!$B$10:$B$16,0)),'Travel Matrix'!$D$6:$GT$6,0))*IF(INDEX('Travel Matrix'!$D$7:$GT$205,MATCH(INDEX('Inputs (detail)'!$E$10:$E$16,MATCH($B11,'Inputs (detail)'!$B$10:$B$16,0)),'Travel Matrix'!$C$7:$C$205,0),MATCH(INDEX('Inputs (detail)'!$E$10:$E$16,MATCH(F$10,'Inputs (detail)'!$B$10:$B$16,0)),'Travel Matrix'!$D$6:$GT$6,0))>Assumptions!$E$37,IF(F$9="Plane (Economy)",Assumptions!$E$35,Assumptions!$E$36),IF(F$9="Plane (Economy)",Assumptions!$E$33,Assumptions!$E$34))) -> 127.00242 | G11: =IF($B11=G$10,0,INDEX('Travel Matrix'!$D$7:$GT$205,MATCH(INDEX('Inputs (detail)'!$E$10:$E$16,MATCH($B11,'Inputs (detail)'!$B$10:$B$16,0)),'Travel Matrix'!$C$7:$C$205,0),MATCH(INDEX('Inputs (detail)'!$E$10:$E$16,MATCH(G$10,'Inputs (detail)'!$B$10:$B$16,0)),'Travel Matrix'!$D$6:$GT$6,0))*IF(INDEX('Travel Matrix'!$D$7:$GT$205,MATCH(INDEX('Inputs (detail)'!$E$10:$E$16,MATCH($B11,'Inputs (detail)'!$B$10:$B$16,0)),'Travel Matrix'!$C$7:$C$205,0),MATCH(INDEX('Inputs (detail)'!$E$10:$E$16,MATCH(G$10,'Inputs (detail)'!$B$10:$B$16,0)),'Travel Matrix'!$D$6:$GT$6,0))>Assumptions!$E$37,IF(G$9="Plane (Economy)",Assumptions!$E$35,Assumptions!$E$36),IF(G$9="Plane (Economy)",Assumptions!$E$33,Assumptions!$E$34))) -> 0 | H11: =IF($B11=H$10,0,INDEX('Travel Matrix'!$D$7:$GT$205,MATCH(INDEX('Inputs (detail)'!$E$10:$E$16,MATCH($B11,'Inputs (detail)'!$B$10:$B$16,0)),'Travel Matrix'!$C$7:$C$205,0),MATCH(INDEX('Inputs (detail)'!$E$10:$E$16,MATCH(H$10,'Inputs (detail)'!$B$10:$B$16,0)),'Travel Matrix'!$D$6:$GT$6,0))*IF(INDEX('Travel Matrix'!$D$7:$GT$205,MATCH(INDEX('Inputs (detail)'!$E$10:$E$16,MATCH($B11,'Inputs (detail)'!$B$10:$B$16,0)),'Travel Matrix'!$C$7:$C$205,0),MATCH(INDEX('Inputs (detail)'!$E$10:$E$16,MATCH(H$10,'Inputs (detail)'!$B$10:$B$16,0)),'Travel Matrix'!$D$6:$GT$6,0))>Assumptions!$E$37,IF(H$9="Plane (Economy)",Assumptions!$E$35,Assumptions!$E$36),IF(H$9="Plane (Economy)",Assumptions!$E$33,Assumptions!$E$34))) -> 406.1469 | I11: =IF($B11=I$10,0,INDEX('Travel Matrix'!$D$7:$GT$205,MATCH(INDEX('Inputs (detail)'!$E$10:$E$16,MATCH($B11,'Inputs (detail)'!$B$10:$B$16,0)),'Travel Matrix'!$C$7:$C$205,0),MATCH(INDEX('Inputs (detail)'!$E$10:$E$16,MATCH(I$10,'Inputs (detail)'!$B$10:$B$16,0)),'Travel Matrix'!$D$6:$GT$6,0))*IF(INDEX('Travel Matrix'!$D$7:$GT$205,MATCH(INDEX('Inputs (detail)'!$E$10:$E$16,MATCH($B11,'Inputs (detail)'!$B$10:$B$16,0)),'Travel Matrix'!$C$7:$C$205,0),MATCH(INDEX('Inputs (detail)'!$E$10:$E$16,MATCH(I$10,'Inputs (detail)'!$B$10:$B$16,0)),'Travel Matrix'!$D$6:$GT$6,0))>Assumptions!$E$37,IF(I$9="Plane (Economy)",Assumptions!$E$35,Assumptions!$E$36),IF(I$9="Plane (Economy)",Assumptions!$E$33,Assumptions!$E$34))) -> 249.1049 | J11: =IF($B11=J$10,0,INDEX('Travel Matrix'!$D$7:$GT$205,MATCH(INDEX('Inputs (detail)'!$E$10:$E$16,MATCH($B11,'Inputs (detail)'!$B$10:$B$16,0)),'Travel Matrix'!$C$7:$C$205,0),MATCH(INDEX('Inputs (detail)'!$E$10:$E$16,MATCH(J$10,'Inputs (detail)'!$B$10:$B$16,0)),'Travel Matrix'!$D$6:$GT$6,0))*IF(INDEX('Travel Matrix'!$D$7:$GT$205,MATCH(INDEX('Inputs (detail)'!$E$10:$E$16,MATCH($B11,'Inputs (detail)'!$B$10:$B$16,0)),'Travel Matrix'!$C$7:$C$205,0),MATCH(INDEX('Inputs (detail)'!$E$10:$E$16,MATCH(J$10,'Inputs (detail)'!$B$10:$B$16,0)),'Travel Matrix'!$D$6:$GT$6,0))>Assumptions!$E$37,IF(J$9="Plane (Economy)",Assumptions!$E$35,Assumptions!$E$36),IF(J$9="Plane (Economy)",Assumptions!$E$33,Assumptions!$E$34))) -> 190.50283 | K11: =IF($B11=K$10,0,INDEX('Travel Matrix'!$D$7:$GT$205,MATCH(INDEX('Inputs (detail)'!$E$10:$E$16,MATCH($B11,'Inputs (detail)'!$B$10:$B$16,0)),'Travel Matrix'!$C$7:$C$205,0),MATCH(INDEX('Inputs (detail)'!$E$10:$E$16,MATCH(K$10,'Inputs (detail)'!$B$10:$B$16,0)),'Travel Matrix'!$D$6:$GT$6,0)))*Assumptions!$E$38 -> 0 | L11: =IF($B11=L$10,0,INDEX('Travel Matrix'!$D$7:$GT$205,MATCH(INDEX('Inputs (detail)'!$E$10:$E$16,MATCH($B11,'Inputs (detail)'!$B$10:$B$16,0)),'Travel Matrix'!$C$7:$C$205,0),MATCH(INDEX('Inputs (detail)'!$E$10:$E$16,MATCH(L$10,'Inputs (detail)'!$B$10:$B$16,0)),'Travel Matrix'!$D$6:$GT$6,0)))*Assumptions!$E$38 -> 29.55531 | M11: =IF($B11=M$10,0,INDEX('Travel Matrix'!$D$7:$GT$205,MATCH(INDEX('Inputs (detail)'!$E$10:$E$16,MATCH($B11,'Inputs (detail)'!$B$10:$B$16,0)),'Travel Matrix'!$C$7:$C$205,0),MATCH(INDEX('Inputs (detail)'!$E$10:$E$16,MATCH(M$10,'Inputs (detail)'!$B$10:$B$16,0)),'Travel Matrix'!$D$6:$GT$6,0)))*Assumptions!$E$38 -> 18.127364 | N11: =IF($B11=N$10,0,INDEX('Travel Matrix'!$D$7:$GT$205,MATCH(INDEX('Inputs (detail)'!$E$10:$E$16,MATCH($B11,'Inputs (detail)'!$B$10:$B$16,0)),'Travel Matrix'!$C$7:$C$205,0),MATCH(INDEX('Inputs (detail)'!$E$10:$E$16,MATCH(N$10,'Inputs (detail)'!$B$10:$B$16,0)),'Travel Matrix'!$D$6:$GT$6,0)))*Assumptions!$E$38 -> 13.862891 | O11: =IF($B11=O$10,0,INDEX('Travel Matrix'!$D$7:$GT$205,MATCH(INDEX('Inputs (detail)'!$E$10:$E$16,MATCH($B11,'Inputs (detail)'!$B$10:$B$16,0)),'Travel Matrix'!$C$7:$C$205,0),MATCH(INDEX('Inputs (detail)'!$E$10:$E$16,MATCH(O$10,'Inputs (detail)'!$B$10:$B$16,0)),'Travel Matrix'!$D$6:$GT$6,0)))*Assumptions!$E$31 -> 0 | P11: =IF($B11=P$10,0,INDEX('Travel Matrix'!$D$7:$GT$205,MATCH(INDEX('Inputs (detail)'!$E$10:$E$16,MATCH($B11,'Inputs (detail)'!$B$10:$B$16,0)),'Travel Matrix'!$C$7:$C$205,0),MATCH(INDEX('Inputs (detail)'!$E$10:$E$16,MATCH(P$10,'Inputs (detail)'!$B$10:$B$16,0)),'Travel Matrix'!$D$6:$GT$6,0)))*Assumptions!$E$31 -> 223.43697 | Q11: =IF($B11=Q$10,0,INDEX('Travel Matrix'!$D$7:$GT$205,MATCH(INDEX('Inputs (detail)'!$E$10:$E$16,MATCH($B11,'Inputs (detail)'!$B$10:$B$16,0)),'Travel Matrix'!$C$7:$C$205,0),MATCH(INDEX('Inputs (detail)'!$E$10:$E$16,MATCH(Q$10,'Inputs (detail)'!$B$10:$B$16,0)),'Travel Matrix'!$D$6:$GT$6,0)))*Assumptions!$E$31 -> 137.04215 | R11: =IF($B11=R$10,0,INDEX('Travel Matrix'!$D$7:$GT$205,MATCH(INDEX('Inputs (detail)'!$E$10:$E$16,MATCH($B11,'Inputs (detail)'!$B$10:$B$16,0)),'Travel Matrix'!$C$7:$C$205,0),MATCH(INDEX('Inputs (detail)'!$E$10:$E$16,MATCH(R$10,'Inputs (detail)'!$B$10:$B$16,0)),'Travel Matrix'!$D$6:$GT$6,0)))*Assumptions!$E$31 -> 104.80291 | S11: =IF($B11=S$10,0,INDEX('Travel Matrix'!$D$7:$GT$205,MATCH(INDEX('Inputs (detail)'!$E$10:$E$16,MATCH($B11,'Inputs (detail)'!$B$10:$B$16,0)),'Travel Matrix'!$C$7:$C$205,0),MATCH(INDEX('Inputs (detail)'!$E$10:$E$16,MATCH(S$10,'Inputs (detail)'!$B$10:$B$16,0)),'Travel Matrix'!$D$6:$GT$6,0)))*Assumptions!$E$32 -> 0 | T11: =IF($B11=T$10,0,INDEX('Travel Matrix'!$D$7:$GT$205,MATCH(INDEX('Inputs (detail)'!$E$10:$E$16,MATCH($B11,'Inputs (detail)'!$B$10:$B$16,0)),'Travel Matrix'!$C$7:$C$205,0),MATCH(INDEX('Inputs (detail)'!$E$10:$E$16,MATCH(T$10,'Inputs (detail)'!$B$10:$B$16,0)),'Travel Matrix'!$D$6:$GT$6,0)))*Assumptions!$E$32 -> 81.134419 | U11: =IF($B11=U$10,0,INDEX('Travel Matrix'!$D$7:$GT$205,MATCH(INDEX('Inputs (detail)'!$E$10:$E$16,MATCH($B11,'Inputs (detail)'!$B$10:$B$16,0)),'Travel Matrix'!$C$7:$C$205,0),MATCH(INDEX('Inputs (detail)'!$E$10:$E$16,MATCH(U$10,'Inputs (detail)'!$B$10:$B$16,0)),'Travel Matrix'!$D$6:$GT$6,0)))*Assumptions!$E$32 -> 49.762738 | V11: =IF($B11=V$10,0,INDEX('Travel Matrix'!$D$7:$GT$205,MATCH(INDEX('Inputs (detail)'!$E$10:$E$16,MATCH($B11,'Inputs (detail)'!$B$10:$B$16,0)),'Travel Matrix'!$C$7:$C$205,0),MATCH(INDEX('Inputs (detail)'!$E$10:$E$16,MATCH(V$10,'Inputs (detail)'!$B$10:$B$16,0)),'Travel Matrix'!$D$6:$GT$6,0)))*Assumptions!$E$32 -> 38.056025
B12: Claimant Counsel | C12: =IF($B12=C$10,0,INDEX('Travel Matrix'!$D$7:$GT$205,MATCH(INDEX('Inputs (detail)'!$E$10:$E$16,MATCH($B12,'Inputs (detail)'!$B$10:$B$16,0)),'Travel Matrix'!$C$7:$C$205,0),MATCH(INDEX('Inputs (detail)'!$E$10:$E$16,MATCH(C$10,'Inputs (detail)'!$B$10:$B$16,0)),'Travel Matrix'!$D$6:$GT$6,0))*IF(INDEX('Travel Matrix'!$D$7:$GT$205,MATCH(INDEX('Inputs (detail)'!$E$10:$E$16,MATCH($B12,'Inputs (detail)'!$B$10:$B$16,0)),'Travel Matrix'!$C$7:$C$205,0),MATCH(INDEX('Inputs (detail)'!$E$10:$E$16,MATCH(C$10,'Inputs (detail)'!$B$10:$B$16,0)),'Travel Matrix'!$D$6:$GT$6,0))>Assumptions!$E$37,IF(C$9="Plane (Economy)",Assumptions!$E$35,Assumptions!$E$36),IF(C$9="Plane (Economy)",Assumptions!$E$33,Assumptions!$E$34))) -> 270.76574 | D12: =IF($B12=D$10,0,INDEX('Travel Matrix'!$D$7:$GT$205,MATCH(INDEX('Inputs (detail)'!$E$10:$E$16,MATCH($B12,'Inputs (detail)'!$B$10:$B$16,0)),'Travel Matrix'!$C$7:$C$205,0),MATCH(INDEX('Inputs (detail)'!$E$10:$E$16,MATCH(D$10,'Inputs (detail)'!$B$10:$B$16,0)),'Travel Matrix'!$D$6:$GT$6,0))*IF(INDEX('Travel Matrix'!$D$7:$GT$205,MATCH(INDEX('Inputs (detail)'!$E$10:$E$16,MATCH($B12,'Inputs (detail)'!$B$10:$B$16,0)),'Travel Matrix'!$C$7:$C$205,0),MATCH(INDEX('Inputs (detail)'!$E$10:$E$16,MATCH(D$10,'Inputs (detail)'!$B$10:$B$16,0)),'Travel Matrix'!$D$6:$GT$6,0))>Assumptions!$E$37,IF(D$9="Plane (Economy)",Assumptions!$E$35,Assumptions!$E$36),IF(D$9="Plane (Economy)",Assumptions!$E$33,Assumptions!$E$34))) -> 0 | E12: =IF($B12=E$10,0,INDEX('Travel Matrix'!$D$7:$GT$205,MATCH(INDEX('Inputs (detail)'!$E$10:$E$16,MATCH($B12,'Inputs (detail)'!$B$10:$B$16,0)),'Travel Matrix'!$C$7:$C$205,0),MATCH(INDEX('Inputs (detail)'!$E$10:$E$16,MATCH(E$10,'Inputs (detail)'!$B$10:$B$16,0)),'Travel Matrix'!$D$6:$GT$6,0))*IF(INDEX('Travel Matrix'!$D$7:$GT$205,MATCH(INDEX('Inputs (detail)'!$E$10:$E$16,MATCH($B12,'Inputs (detail)'!$B$10:$B$16,0)),'Travel Matrix'!$C$7:$C$205,0),MATCH(INDEX('Inputs (detail)'!$E$10:$E$16,MATCH(E$10,'Inputs (detail)'!$B$10:$B$16,0)),'Travel Matrix'!$D$6:$GT$6,0))>Assumptions!$E$37,IF(E$9="Plane (Economy)",Assumptions!$E$35,Assumptions!$E$36),IF(E$9="Plane (Economy)",Assumptions!$E$33,Assumptions!$E$34))) -> 230.9293 | F12: =IF($B12=F$10,0,INDEX('Travel Matrix'!$D$7:$GT$205,MATCH(INDEX('Inputs (detail)'!$E$10:$E$16,MATCH($B12,'Inputs (detail)'!$B$10:$B$16,0)),'Travel Matrix'!$C$7:$C$205,0),MATCH(INDEX('Inputs (detail)'!$E$10:$E$16,MATCH(F$10,'Inputs (detail)'!$B$10:$B$16,0)),'Travel Matrix'!$D$6:$GT$6,0))*IF(INDEX('Travel Matrix'!$D$7:$GT$205,MATCH(INDEX('Inputs (detail)'!$E$10:$E$16,MATCH($B12,'Inputs (detail)'!$B$10:$B$16,0)),'Travel Matrix'!$C$7:$C$205,0),MATCH(INDEX('Inputs (detail)'!$E$10:$E$16,MATCH(F$10,'Inputs (detail)'!$B$10:$B$16,0)),'Travel Matrix'!$D$6:$GT$6,0))>Assumptions!$E$37,IF(F$9="Plane (Economy)",Assumptions!$E$35,Assumptions!$E$36),IF(F$9="Plane (Economy)",Assumptions!$E$33,Assumptions!$E$34))) -> 186.64954 | G12: =IF($B12=G$10,0,INDEX('Travel Matrix'!$D$7:$GT$205,MATCH(INDEX('Inputs (detail)'!$E$10:$E$16,MATCH($B12,'Inputs (detail)'!$B$10:$B$16,0)),'Travel Matrix'!$C$7:$C$205,0),MATCH(INDEX('Inputs (detail)'!$E$10:$E$16,MATCH(G$10,'Inputs (detail)'!$B$10:$B$16,0)),'Travel Matrix'!$D$6:$GT$6,0))*IF(INDEX('Travel Matrix'!$D$7:$GT$205,MATCH(INDEX('Inputs (detail)'!$E$10:$E$16,MATCH($B12,'Inputs (detail)'!$B$10:$B$16,0)),'Travel Matrix'!$C$7:$C$205,0),MATCH(INDEX('Inputs (detail)'!$E$10:$E$16,MATCH(G$10,'Inputs (detail)'!$B$10:$B$16,0)),'Travel Matrix'!$D$6:$GT$6,0))>Assumptions!$E$37,IF(G$9="Plane (Economy)",Assumptions!$E$35,Assumptions!$E$36),IF(G$9="Plane (Economy)",Assumptions!$E$33,Assumptions!$E$34))) -> 406.1469 | H12: =IF($B12=H$10,0,INDEX('Travel Matrix'!$D$7:$GT$205,MATCH(INDEX('Inputs (detail)'!$E$10:$E$16,MATCH($B12,'Inputs (detail)'!$B$10:$B$16,0)),'Travel Matrix'!$C$7:$C$205,0),MATCH(INDEX('Inputs (detail)'!$E$10:$E$16,MATCH(H$10,'Inputs (detail)'!$B$10:$B$16,0)),'Travel Matrix'!$D$6:$GT$6,0))*IF(INDEX('Travel Matrix'!$D$7:$GT$205,MATCH(INDEX('Inputs (detail)'!$E$10:$E$16,MATCH($B12,'Inputs (detail)'!$B$10:$B$16,0)),'Travel Matrix'!$C$7:$C$205,0),MATCH(INDEX('Inputs (detail)'!$E$10:$E$16,MATCH(H$10,'Inputs (detail)'!$B$10:$B$16,0)),'Travel Matrix'!$D$6:$GT$6,0))>Assumptions!$E$37,IF(H$9="Plane (Economy)",Assumptions!$E$35,Assumptions!$E$36),IF(H$9="Plane (Economy)",Assumptions!$E$33,Assumptions!$E$34))) -> 0 | I12: =IF($B12=I$10,0,INDEX('Travel Matrix'!$D$7:$GT$205,MATCH(INDEX('Inputs (detail)'!$E$10:$E$16,MATCH($B12,'Inputs (detail)'!$B$10:$B$16,0)),'Travel Matrix'!$C$7:$C$205,0),MATCH(INDEX('Inputs (detail)'!$E$10:$E$16,MATCH(I$10,'Inputs (detail)'!$B$10:$B$16,0)),'Travel Matrix'!$D$6:$GT$6,0))*IF(INDEX('Travel Matrix'!$D$7:$GT$205,MATCH(INDEX('Inputs (detail)'!$E$10:$E$16,MATCH($B12,'Inputs (detail)'!$B$10:$B$16,0)),'Travel Matrix'!$C$7:$C$205,0),MATCH(INDEX('Inputs (detail)'!$E$10:$E$16,MATCH(I$10,'Inputs (detail)'!$B$10:$B$16,0)),'Travel Matrix'!$D$6:$GT$6,0))>Assumptions!$E$37,IF(I$9="Plane (Economy)",Assumptions!$E$35,Assumptions!$E$36),IF(I$9="Plane (Economy)",Assumptions!$E$33,Assumptions!$E$34))) -> 346.39249 | J12: =IF($B12=J$10,0,INDEX('Travel Matrix'!$D$7:$GT$205,MATCH(INDEX('Inputs (detail)'!$E$10:$E$16,MATCH($B12,'Inputs (detail)'!$B$10:$B$16,0)),'Travel Matrix'!$C$7:$C$205,0),MATCH(INDEX('Inputs (detail)'!$E$10:$E$16,MATCH(J$10,'Inputs (detail)'!$B$10:$B$16,0)),'Travel Matrix'!$D$6:$GT$6,0))*IF(INDEX('Travel Matrix'!$D$7:$GT$205,MATCH(INDEX('Inputs (detail)'!$E$10:$E$16,MATCH($B12,'Inputs (detail)'!$B$10:$B$16,0)),'Travel Matrix'!$C$7:$C$205,0),MATCH(INDEX('Inputs (detail)'!$E$10:$E$16,MATCH(J$10,'Inputs (detail)'!$B$10:$B$16,0)),'Travel Matrix'!$D$6:$GT$6,0))>Assumptions!$E$37,IF(J$9="Plane (Economy)",Assumptions!$E$35,Assumptions!$E$36),IF(J$9="Plane (Economy)",Assumptions!$E$33,Assumptions!$E$34))) -> 279.97313 | K12: =IF($B12=K$10,0,INDEX('Travel Matrix'!$D$7:$GT$205,MATCH(INDEX('Inputs (detail)'!$E$10:$E$16,MATCH($B12,'Inputs (detail)'!$B$10:$B$16,0)),'Travel Matrix'!$C$7:$C$205,0),MATCH(INDEX('Inputs (detail)'!$E$10:$E$16,MATCH(K$10,'Inputs (detail)'!$B$10:$B$16,0)),'Travel Matrix'!$D$6:$GT$6,0)))*Assumptions!$E$38 -> 29.55531 | L12: =IF($B12=L$10,0,INDEX('Travel Matrix'!$D$7:$GT$205,MATCH(INDEX('Inputs (detail)'!$E$10:$E$16,MATCH($B12,'Inputs (detail)'!$B$10:$B$16,0)),'Travel Matrix'!$C$7:$C$205,0),MATCH(INDEX('Inputs (detail)'!$E$10:$E$16,MATCH(L$10,'Inputs (detail)'!$B$10:$B$16,0)),'Travel Matrix'!$D$6:$GT$6,0)))*Assumptions!$E$38 -> 0 | M12: =IF($B12=M$10,0,INDEX('Travel Matrix'!$D$7:$GT$205,MATCH(INDEX('Inputs (detail)'!$E$10:$E$16,MATCH($B12,'Inputs (detail)'!$B$10:$B$16,0)),'Travel Matrix'!$C$7:$C$205,0),MATCH(INDEX('Inputs (detail)'!$E$10:$E$16,MATCH(M$10,'Inputs (detail)'!$B$10:$B$16,0)),'Travel Matrix'!$D$6:$GT$6,0)))*Assumptions!$E$38 -> 25.206982 | N12: =IF($B12=N$10,0,INDEX('Travel Matrix'!$D$7:$GT$205,MATCH(INDEX('Inputs (detail)'!$E$10:$E$16,MATCH($B12,'Inputs (detail)'!$B$10:$B$16,0)),'Travel Matrix'!$C$7:$C$205,0),MATCH(INDEX('Inputs (detail)'!$E$10:$E$16,MATCH(N$10,'Inputs (detail)'!$B$10:$B$16,0)),'Travel Matrix'!$D$6:$GT$6,0)))*Assumptions!$E$38 -> 20.373645 | O12: =IF($B12=O$10,0,INDEX('Travel Matrix'!$D$7:$GT$205,MATCH(INDEX('Inputs (detail)'!$E$10:$E$16,MATCH($B12,'Inputs (detail)'!$B$10:$B$16,0)),'Travel Matrix'!$C$7:$C$205,0),MATCH(INDEX('Inputs (detail)'!$E$10:$E$16,MATCH(O$10,'Inputs (detail)'!$B$10:$B$16,0)),'Travel Matrix'!$D$6:$GT$6,0)))*Assumptions!$E$31 -> 223.43697 | P12: =IF($B12=P$10,0,INDEX('Travel Matrix'!$D$7:$GT$205,MATCH(INDEX('Inputs (detail)'!$E$10:$E$16,MATCH($B12,'Inputs (detail)'!$B$10:$B$16,0)),'Travel Matrix'!$C$7:$C$205,0),MATCH(INDEX('Inputs (detail)'!$E$10:$E$16,MATCH(P$10,'Inputs (detail)'!$B$10:$B$16,0)),'Travel Matrix'!$D$6:$GT$6,0)))*Assumptions!$E$31 -> 0 | Q12: =IF($B12=Q$10,0,INDEX('Travel Matrix'!$D$7:$GT$205,MATCH(INDEX('Inputs (detail)'!$E$10:$E$16,MATCH($B12,'Inputs (detail)'!$B$10:$B$16,0)),'Travel Matrix'!$C$7:$C$205,0),MATCH(INDEX('Inputs (detail)'!$E$10:$E$16,MATCH(Q$10,'Inputs (detail)'!$B$10:$B$16,0)),'Travel Matrix'!$D$6:$GT$6,0)))*Assumptions!$E$31 -> 190.56378 | R12: =IF($B12=R$10,0,INDEX('Travel Matrix'!$D$7:$GT$205,MATCH(INDEX('Inputs (detail)'!$E$10:$E$16,MATCH($B12,'Inputs (detail)'!$B$10:$B$16,0)),'Travel Matrix'!$C$7:$C$205,0),MATCH(INDEX('Inputs (detail)'!$E$10:$E$16,MATCH(R$10,'Inputs (detail)'!$B$10:$B$16,0)),'Travel Matrix'!$D$6:$GT$6,0)))*Assumptions!$E$31 -> 154.02394 | S12: =IF($B12=S$10,0,INDEX('Travel Matrix'!$D$7:$GT$205,MATCH(INDEX('Inputs (detail)'!$E$10:$E$16,MATCH($B12,'Inputs (detail)'!$B$10:$B$16,0)),'Travel Matrix'!$C$7:$C$205,0),MATCH(INDEX('Inputs (detail)'!$E$10:$E$16,MATCH(S$10,'Inputs (detail)'!$B$10:$B$16,0)),'Travel Matrix'!$D$6:$GT$6,0)))*Assumptions!$E$32 -> 81.134419 | T12: =IF($B12=T$10,0,INDEX('Travel Matrix'!$D$7:$GT$205,MATCH(INDEX('Inputs (detail)'!$E$10:$E$16,MATCH($B12,'Inputs (detail)'!$B$10:$B$16,0)),'Travel Matrix'!$C$7:$C$205,0),MATCH(INDEX('Inputs (detail)'!$E$10:$E$16,MATCH(T$10,'Inputs (detail)'!$B$10:$B$16,0)),'Travel Matrix'!$D$6:$GT$6,0)))*Assumptions!$E$32 -> 0 | U12: =IF($B12=U$10,0,INDEX('Travel Matrix'!$D$7:$GT$205,MATCH(INDEX('Inputs (detail)'!$E$10:$E$16,MATCH($B12,'Inputs (detail)'!$B$10:$B$16,0)),'Travel Matrix'!$C$7:$C$205,0),MATCH(INDEX('Inputs (detail)'!$E$10:$E$16,MATCH(U$10,'Inputs (detail)'!$B$10:$B$16,0)),'Travel Matrix'!$D$6:$GT$6,0)))*Assumptions!$E$32 -> 69.197508 | V12: =IF($B12=V$10,0,INDEX('Travel Matrix'!$D$7:$GT$205,MATCH(INDEX('Inputs (detail)'!$E$10:$E$16,MATCH($B12,'Inputs (detail)'!$B$10:$B$16,0)),'Travel Matrix'!$C$7:$C$205,0),MATCH(INDEX('Inputs (detail)'!$E$10:$E$16,MATCH(V$10,'Inputs (detail)'!$B$10:$B$16,0)),'Travel Matrix'!$D$6:$GT$6,0)))*Assumptions!$E$32 -> 55.929165
B13: Claimant Expert | C13: =IF($B13=C$10,0,INDEX('Travel Matrix'!$D$7:$GT$205,MATCH(INDEX('Inputs (detail)'!$E$10:$E$16,MATCH($B13,'Inputs (detail)'!$B$10:$B$16,0)),'Travel Matrix'!$C$7:$C$205,0),MATCH(INDEX('Inputs (detail)'!$E$10:$E$16,MATCH(C$10,'Inputs (detail)'!$B$10:$B$16,0)),'Travel Matrix'!$D$6:$GT$6,0))*IF(INDEX('Travel Matrix'!$D$7:$GT$205,MATCH(INDEX('Inputs (detail)'!$E$10:$E$16,MATCH($B13,'Inputs (detail)'!$B$10:$B$16,0)),'Travel Matrix'!$C$7:$C$205,0),MATCH(INDEX('Inputs (detail)'!$E$10:$E$16,MATCH(C$10,'Inputs (detail)'!$B$10:$B$16,0)),'Travel Matrix'!$D$6:$GT$6,0))>Assumptions!$E$37,IF(C$9="Plane (Economy)",Assumptions!$E$35,Assumptions!$E$36),IF(C$9="Plane (Economy)",Assumptions!$E$33,Assumptions!$E$34))) -> 166.07063 | D13: =IF($B13=D$10,0,INDEX('Travel Matrix'!$D$7:$GT$205,MATCH(INDEX('Inputs (detail)'!$E$10:$E$16,MATCH($B13,'Inputs (detail)'!$B$10:$B$16,0)),'Travel Matrix'!$C$7:$C$205,0),MATCH(INDEX('Inputs (detail)'!$E$10:$E$16,MATCH(D$10,'Inputs (detail)'!$B$10:$B$16,0)),'Travel Matrix'!$D$6:$GT$6,0))*IF(INDEX('Travel Matrix'!$D$7:$GT$205,MATCH(INDEX('Inputs (detail)'!$E$10:$E$16,MATCH($B13,'Inputs (detail)'!$B$10:$B$16,0)),'Travel Matrix'!$C$7:$C$205,0),MATCH(INDEX('Inputs (detail)'!$E$10:$E$16,MATCH(D$10,'Inputs (detail)'!$B$10:$B$16,0)),'Travel Matrix'!$D$6:$GT$6,0))>Assumptions!$E$37,IF(D$9="Plane (Economy)",Assumptions!$E$35,Assumptions!$E$36),IF(D$9="Plane (Economy)",Assumptions!$E$33,Assumptions!$E$34))) -> 230.9293 | E13: =IF($B13=E$10,0,INDEX('Travel Matrix'!$D$7:$GT$205,MATCH(INDEX('Inputs (detail)'!$E$10:$E$16,MATCH($B13,'Inputs (detail)'!$B$10:$B$16,0)),'Travel Matrix'!$C$7:$C$205,0),MATCH(INDEX('Inputs (detail)'!$E$10:$E$16,MATCH(E$10,'Inputs (detail)'!$B$10:$B$16,0)),'Travel Matrix'!$D$6:$GT$6,0))*IF(INDEX('Travel Matrix'!$D$7:$GT$205,MATCH(INDEX('Inputs (detail)'!$E$10:$E$16,MATCH($B13,'Inputs (detail)'!$B$10:$B$16,0)),'Travel Matrix'!$C$7:$C$205,0),MATCH(INDEX('Inputs (detail)'!$E$10:$E$16,MATCH(E$10,'Inputs (detail)'!$B$10:$B$16,0)),'Travel Matrix'!$D$6:$GT$6,0))>Assumptions!$E$37,IF(E$9="Plane (Economy)",Assumptions!$E$35,Assumptions!$E$36),IF(E$9="Plane (Economy)",Assumptions!$E$33,Assumptions!$E$34))) -> 0 | F13: =IF($B13=F$10,0,INDEX('Travel Matrix'!$D$7:$GT$205,MATCH(INDEX('Inputs (detail)'!$E$10:$E$16,MATCH($B13,'Inputs (detail)'!$B$10:$B$16,0)),'Travel Matrix'!$C$7:$C$205,0),MATCH(INDEX('Inputs (detail)'!$E$10:$E$16,MATCH(F$10,'Inputs (detail)'!$B$10:$B$16,0)),'Travel Matrix'!$D$6:$GT$6,0))*IF(INDEX('Travel Matrix'!$D$7:$GT$205,MATCH(INDEX('Inputs (detail)'!$E$10:$E$16,MATCH($B13,'Inputs (detail)'!$B$10:$B$16,0)),'Travel Matrix'!$C$7:$C$205,0),MATCH(INDEX('Inputs (detail)'!$E$10:$E$16,MATCH(F$10,'Inputs (detail)'!$B$10:$B$16,0)),'Travel Matrix'!$D$6:$GT$6,0))>Assumptions!$E$37,IF(F$9="Plane (Economy)",Assumptions!$E$35,Assumptions!$E$36),IF(F$9="Plane (Economy)",Assumptions!$E$33,Assumptions!$E$34))) -> 65.180227 | G13: =IF($B13=G$10,0,INDEX('Travel Matrix'!$D$7:$GT$205,MATCH(INDEX('Inputs (detail)'!$E$10:$E$16,MATCH($B13,'Inputs (detail)'!$B$10:$B$16,0)),'Travel Matrix'!$C$7:$C$205,0),MATCH(INDEX('Inputs (detail)'!$E$10:$E$16,MATCH(G$10,'Inputs (detail)'!$B$10:$B$16,0)),'Travel Matrix'!$D$6:$GT$6,0))*IF(INDEX('Travel Matrix'!$D$7:$GT$205,MATCH(INDEX('Inputs (detail)'!$E$10:$E$16,MATCH($B13,'Inputs (detail)'!$B$10:$B$16,0)),'Travel Matrix'!$C$7:$C$205,0),MATCH(INDEX('Inputs (detail)'!$E$10:$E$16,MATCH(G$10,'Inputs (detail)'!$B$10:$B$16,0)),'Travel Matrix'!$D$6:$GT$6,0))>Assumptions!$E$37,IF(G$9="Plane (Economy)",Assumptions!$E$35,Assumptions!$E$36),IF(G$9="Plane (Economy)",Assumptions!$E$33,Assumptions!$E$34))) -> 249.1049 | H13: =IF($B13=H$10,0,INDEX('Travel Matrix'!$D$7:$GT$205,MATCH(INDEX('Inputs (detail)'!$E$10:$E$16,MATCH($B13,'Inputs (detail)'!$B$10:$B$16,0)),'Travel Matrix'!$C$7:$C$205,0),MATCH(INDEX('Inputs (detail)'!$E$10:$E$16,MATCH(H$10,'Inputs (detail)'!$B$10:$B$16,0)),'Travel Matrix'!$D$6:$GT$6,0))*IF(INDEX('Travel Matrix'!$D$7:$GT$205,MATCH(INDEX('Inputs (detail)'!$E$10:$E$16,MATCH($B13,'Inputs (detail)'!$B$10:$B$16,0)),'Travel Matrix'!$C$7:$C$205,0),MATCH(INDEX('Inputs (detail)'!$E$10:$E$16,MATCH(H$10,'Inputs (detail)'!$B$10:$B$16,0)),'Travel Matrix'!$D$6:$GT$6,0))>Assumptions!$E$37,IF(H$9="Plane (Economy)",Assumptions!$E$35,Assumptions!$E$36),IF(H$9="Plane (Economy)",Assumptions!$E$33,Assumptions!$E$34))) -> 346.39249 | I13: =IF($B13=I$10,0,INDEX('Travel Matrix'!$D$7:$GT$205,MATCH(INDEX('Inputs (detail)'!$E$10:$E$16,MATCH($B13,'Inputs (detail)'!$B$10:$B$16,0)),'Travel Matrix'!$C$7:$C$205,0),MATCH(INDEX('Inputs (detail)'!$E$10:$E$16,MATCH(I$10,'Inputs (detail)'!$B$10:$B$16,0)),'Travel Matrix'!$D$6:$GT$6,0))*IF(INDEX('Travel Matrix'!$D$7:$GT$205,MATCH(INDEX('Inputs (detail)'!$E$10:$E$16,MATCH($B13,'Inputs (detail)'!$B$10:$B$16,0)),'Travel Matrix'!$C$7:$C$205,0),MATCH(INDEX('Inputs (detail)'!$E$10:$E$16,MATCH(I$10,'Inputs (detail)'!$B$10:$B$16,0)),'Travel Matrix'!$D$6:$GT$6,0))>Assumptions!$E$37,IF(I$9="Plane (Economy)",Assumptions!$E$35,Assumptions!$E$36),IF(I$9="Plane (Economy)",Assumptions!$E$33,Assumptions!$E$34))) -> 0 | J13: =IF($B13=J$10,0,INDEX('Travel Matrix'!$D$7:$GT$205,MATCH(INDEX('Inputs (detail)'!$E$10:$E$16,MATCH($B13,'Inputs (detail)'!$B$10:$B$16,0)),'Travel Matrix'!$C$7:$C$205,0),MATCH(INDEX('Inputs (detail)'!$E$10:$E$16,MATCH(J$10,'Inputs (detail)'!$B$10:$B$16,0)),'Travel Matrix'!$D$6:$GT$6,0))*IF(INDEX('Travel Matrix'!$D$7:$GT$205,MATCH(INDEX('Inputs (detail)'!$E$10:$E$16,MATCH($B13,'Inputs (detail)'!$B$10:$B$16,0)),'Travel Matrix'!$C$7:$C$205,0),MATCH(INDEX('Inputs (detail)'!$E$10:$E$16,MATCH(J$10,'Inputs (detail)'!$B$10:$B$16,0)),'Travel Matrix'!$D$6:$GT$6,0))>Assumptions!$E$37,IF(J$9="Plane (Economy)",Assumptions!$E$35,Assumptions!$E$36),IF(J$9="Plane (Economy)",Assumptions!$E$33,Assumptions!$E$34))) -> 97.769929 | K13: =IF($B13=K$10,0,INDEX('Travel Matrix'!$D$7:$GT$205,MATCH(INDEX('Inputs (detail)'!$E$10:$E$16,MATCH($B13,'Inputs (detail)'!$B$10:$B$16,0)),'Travel Matrix'!$C$7:$C$205,0),MATCH(INDEX('Inputs (detail)'!$E$10:$E$16,MATCH(K$10,'Inputs (detail)'!$B$10:$B$16,0)),'Travel Matrix'!$D$6:$GT$6,0)))*Assumptions!$E$38 -> 18.127364 | L13: =IF($B13=L$10,0,INDEX('Travel Matrix'!$D$7:$GT$205,MATCH(INDEX('Inputs (detail)'!$E$10:$E$16,MATCH($B13,'Inputs (detail)'!$B$10:$B$16,0)),'Travel Matrix'!$C$7:$C$205,0),MATCH(INDEX('Inputs (detail)'!$E$10:$E$16,MATCH(L$10,'Inputs (detail)'!$B$10:$B$16,0)),'Travel Matrix'!$D$6:$GT$6,0)))*Assumptions!$E$38 -> 25.206982 | M13: =IF($B13=M$10,0,INDEX('Travel Matrix'!$D$7:$GT$205,MATCH(INDEX('Inputs (detail)'!$E$10:$E$16,MATCH($B13,'Inputs (detail)'!$B$10:$B$16,0)),'Travel Matrix'!$C$7:$C$205,0),MATCH(INDEX('Inputs (detail)'!$E$10:$E$16,MATCH(M$10,'Inputs (detail)'!$B$10:$B$16,0)),'Travel Matrix'!$D$6:$GT$6,0)))*Assumptions!$E$38 -> 0 | N13: =IF($B13=N$10,0,INDEX('Travel Matrix'!$D$7:$GT$205,MATCH(INDEX('Inputs (detail)'!$E$10:$E$16,MATCH($B13,'Inputs (detail)'!$B$10:$B$16,0)),'Travel Matrix'!$C$7:$C$205,0),MATCH(INDEX('Inputs (detail)'!$E$10:$E$16,MATCH(N$10,'Inputs (detail)'!$B$10:$B$16,0)),'Travel Matrix'!$D$6:$GT$6,0)))*Assumptions!$E$38 -> 7.1147178 | O13: =IF($B13=O$10,0,INDEX('Travel Matrix'!$D$7:$GT$205,MATCH(INDEX('Inputs (detail)'!$E$10:$E$16,MATCH($B13,'Inputs (detail)'!$B$10:$B$16,0)),'Travel Matrix'!$C$7:$C$205,0),MATCH(INDEX('Inputs (detail)'!$E$10:$E$16,MATCH(O$10,'Inputs (detail)'!$B$10:$B$16,0)),'Travel Matrix'!$D$6:$GT$6,0)))*Assumptions!$E$31 -> 137.04215 | P13: =IF($B13=P$10,0,INDEX('Travel Matrix'!$D$7:$GT$205,MATCH(INDEX('Inputs (detail)'!$E$10:$E$16,MATCH($B13,'Inputs (detail)'!$B$10:$B$16,0)),'Travel Matrix'!$C$7:$C$205,0),MATCH(INDEX('Inputs (detail)'!$E$10:$E$16,MATCH(P$10,'Inputs (detail)'!$B$10:$B$16,0)),'Travel Matrix'!$D$6:$GT$6,0)))*Assumptions!$E$31 -> 190.56378 | Q13: =IF($B13=Q$10,0,INDEX('Travel Matrix'!$D$7:$GT$205,MATCH(INDEX('Inputs (detail)'!$E$10:$E$16,MATCH($B13,'Inputs (detail)'!$B$10:$B$16,0)),'Travel Matrix'!$C$7:$C$205,0),MATCH(INDEX('Inputs (detail)'!$E$10:$E$16,MATCH(Q$10,'Inputs (detail)'!$B$10:$B$16,0)),'Travel Matrix'!$D$6:$GT$6,0)))*Assumptions!$E$31 -> 0 | R13: =IF($B13=R$10,0,INDEX('Travel Matrix'!$D$7:$GT$205,MATCH(INDEX('Inputs (detail)'!$E$10:$E$16,MATCH($B13,'Inputs (detail)'!$B$10:$B$16,0)),'Travel Matrix'!$C$7:$C$205,0),MATCH(INDEX('Inputs (detail)'!$E$10:$E$16,MATCH(R$10,'Inputs (detail)'!$B$10:$B$16,0)),'Travel Matrix'!$D$6:$GT$6,0)))*Assumptions!$E$31 -> 53.786984 | S13: =IF($B13=S$10,0,INDEX('Travel Matrix'!$D$7:$GT$205,MATCH(INDEX('Inputs (detail)'!$E$10:$E$16,MATCH($B13,'Inputs (detail)'!$B$10:$B$16,0)),'Travel Matrix'!$C$7:$C$205,0),MATCH(INDEX('Inputs (detail)'!$E$10:$E$16,MATCH(S$10,'Inputs (detail)'!$B$10:$B$16,0)),'Travel Matrix'!$D$6:$GT$6,0)))*Assumptions!$E$32 -> 49.762738 | T13: =IF($B13=T$10,0,INDEX('Travel Matrix'!$D$7:$GT$205,MATCH(INDEX('Inputs (detail)'!$E$10:$E$16,MATCH($B13,'Inputs (detail)'!$B$10:$B$16,0)),'Travel Matrix'!$C$7:$C$205,0),MATCH(INDEX('Inputs (detail)'!$E$10:$E$16,MATCH(T$10,'Inputs (detail)'!$B$10:$B$16,0)),'Travel Matrix'!$D$6:$GT$6,0)))*Assumptions!$E$32 -> 69.197508 | U13: =IF($B13=U$10,0,INDEX('Travel Matrix'!$D$7:$GT$205,MATCH(INDEX('Inputs (detail)'!$E$10:$E$16,MATCH($B13,'Inputs (detail)'!$B$10:$B$16,0)),'Travel Matrix'!$C$7:$C$205,0),MATCH(INDEX('Inputs (detail)'!$E$10:$E$16,MATCH(U$10,'Inputs (detail)'!$B$10:$B$16,0)),'Travel Matrix'!$D$6:$GT$6,0)))*Assumptions!$E$32 -> 0 | V13: =IF($B13=V$10,0,INDEX('Travel Matrix'!$D$7:$GT$205,MATCH(INDEX('Inputs (detail)'!$E$10:$E$16,MATCH($B13,'Inputs (detail)'!$B$10:$B$16,0)),'Travel Matrix'!$C$7:$C$205,0),MATCH(INDEX('Inputs (detail)'!$E$10:$E$16,MATCH(V$10,'Inputs (detail)'!$B$10:$B$16,0)),'Travel Matrix'!$D$6:$GT$6,0)))*Assumptions!$E$32 -> 19.531126
C15: Plane (Economy) | D15: Plane (Business) | E15: Rail | F15: Car (non-electric) | G15: Car (electric)
B16: Counsel transport to Claimant | C16: =D11 -> 270.76574 | D16: =H11 -> 406.1469 | E16: =L11 -> 29.55531 | F16: =P11 -> 223.43697 | G16: =T11 -> 81.134419
B17: Expert transport to Claimant | C17: =E11 -> 166.07063 | D17: =I11 -> 249.1049 | E17: =M11 -> 18.127364 | F17: =Q11 -> 137.04215 | G17: =U11 -> 49.762738
B18: Claimant transport to Counsel | C18: =C12 -> 270.76574 | D18: =G12 -> 406.1469 | E18: =K12 -> 29.55531 | F18: =O12 -> 223.43697 | G18: =S12 -> 81.134419
B19: Expert transport to Counsel | C19: =E12 -> 230.9293 | D19: =I12 -> 346.39249 | E19: =M12 -> 25.206982 | F19: =Q12 -> 190.56378 | G19: =U12 -> 69.197508
B20: Claimant transport to Expert | C20: =C13 -> 166.07063 | D20: =G13 -> 249.1049 | E20: =K13 -> 18.127364 | F20: =O13 -> 137.04215 | G20: =S13 -> 49.762738
B21: Counsel transport to Expert | C21: =D13 -> 230.9293 | D21: =H13 -> 346.39249 | E21: =L13 -> 25.206982 | F21: =P13 -> 190.56378 | G21: =T13 -> 69.197508
B22: Claimant transport to Hearing | C22: =F11 -> 127.00242 | D22: =J11 -> 190.50283 | E22: =N11 -> 13.862891 | F22: =R11 -> 104.80291 | G22: =V11 -> 38.056025
B23: Counsel transport to Hearing | C23: =F12 -> 186.64954 | D23: =J12 -> 279.97313 | E23: =N12 -> 20.373645 | F23: =R12 -> 154.02394 | G23: =V12 -> 55.929165
B24: Expert transport to Hearing | C24: =F13 -> 65.180227 | D24: =J13 -> 97.769929 | E24: =N13 -> 7.1147178 | F24: =R13 -> 53.786984 | G24: =V13 -> 19.531126
C27: Plane (Economy) | D27: Plane (Economy) | E27: Plane (Economy) | F27: Plane (Economy) | G27: Plane (Business) | H27: Plane (Business) | I27: Plane (Business) | J27: Plane (Business) | K27: Rail | L27: Rail | M27: Rail | N27: Rail | O27: Car (non-electric) | P27: Car (non-electric) | Q27: Car (non-electric) | R27: Car (non-electric) | S27: Car (electric) | T27: Car (electric) | U27: Car (electric) | V27: Car (electric)
C28: Respondent | D28: Respondent Counsel | E28: Respondent Expert | F28: Hearing | G28: Respondent | H28: Respondent Counsel | I28: Respondent Expert | J28: Hearing | K28: Respondent | L28: Respondent Counsel | M28: Respondent Expert | N28: Hearing | O28: Respondent | P28: Respondent Counsel | Q28: Respondent Expert | R28: Hearing | S28: Respondent | T28: Respondent Counsel | U28: Respondent Expert | V28: Hearing
B29: Respondent | C29: =IF($B29=C$28,0,INDEX('Travel Matrix'!$D$7:$GT$205,MATCH(INDEX('Inputs (detail)'!$E$10:$E$16,MATCH($B29,'Inputs (detail)'!$B$10:$B$16,0)),'Travel Matrix'!$C$7:$C$205,0),MATCH(INDEX('Inputs (detail)'!$E$10:$E$16,MATCH(C$28,'Inputs (detail)'!$B$10:$B$16,0)),'Travel Matrix'!$D$6:$GT$6,0))*IF(INDEX('Travel Matrix'!$D$7:$GT$205,MATCH(INDEX('Inputs (detail)'!$E$10:$E$16,MATCH($B29,'Inputs (detail)'!$B$10:$B$16,0)),'Travel Matrix'!$C$7:$C$205,0),MATCH(INDEX('Inputs (detail)'!$E$10:$E$16,MATCH(C$28,'Inputs (detail)'!$B$10:$B$16,0)),'Travel Matrix'!$D$6:$GT$6,0))>Assumptions!$E$37,IF(C$27="Plane (Economy)",Assumptions!$E$35,Assumptions!$E$36),IF(C$9="Plane (Economy)",Assumptions!$E$33,Assumptions!$E$34))) -> 0 | D29: =IF($B29=D$28,0,INDEX('Travel Matrix'!$D$7:$GT$205,MATCH(INDEX('Inputs (detail)'!$E$10:$E$16,MATCH($B29,'Inputs (detail)'!$B$10:$B$16,0)),'Travel Matrix'!$C$7:$C$205,0),MATCH(INDEX('Inputs (detail)'!$E$10:$E$16,MATCH(D$28,'Inputs (detail)'!$B$10:$B$16,0)),'Travel Matrix'!$D$6:$GT$6,0))*IF(INDEX('Travel Matrix'!$D$7:$GT$205,MATCH(INDEX('Inputs (detail)'!$E$10:$E$16,MATCH($B29,'Inputs (detail)'!$B$10:$B$16,0)),'Travel Matrix'!$C$7:$C$205,0),MATCH(INDEX('Inputs (detail)'!$E$10:$E$16,MATCH(D$28,'Inputs (detail)'!$B$10:$B$16,0)),'Travel Matrix'!$D$6:$GT$6,0))>Assumptions!$E$37,IF(D$27="Plane (Economy)",Assumptions!$E$35,Assumptions!$E$36),IF(D$9="Plane (Economy)",Assumptions!$E$33,Assumptions!$E$34))) -> 94.740474 | E29: =IF($B29=E$28,0,INDEX('Travel Matrix'!$D$7:$GT$205,MATCH(INDEX('Inputs (detail)'!$E$10:$E$16,MATCH($B29,'Inputs (detail)'!$B$10:$B$16,0)),'Travel Matrix'!$C$7:$C$205,0),MATCH(INDEX('Inputs (detail)'!$E$10:$E$16,MATCH(E$28,'Inputs (detail)'!$B$10:$B$16,0)),'Travel Matrix'!$D$6:$GT$6,0))*IF(INDEX('Travel Matrix'!$D$7:$GT$205,MATCH(INDEX('Inputs (detail)'!$E$10:$E$16,MATCH($B29,'Inputs (detail)'!$B$10:$B$16,0)),'Travel Matrix'!$C$7:$C$205,0),MATCH(INDEX('Inputs (detail)'!$E$10:$E$16,MATCH(E$28,'Inputs (detail)'!$B$10:$B$16,0)),'Travel Matrix'!$D$6:$GT$6,0))>Assumptions!$E$37,IF(E$27="Plane (Economy)",Assumptions!$E$35,Assumptions!$E$36),IF(E$9="Plane (Economy)",Assumptions!$E$33,Assumptions!$E$34))) -> 172.74633 | F29: =IF($B29=F$28,0,INDEX('Travel Matrix'!$D$7:$GT$205,MATCH(INDEX('Inputs (detail)'!$E$10:$E$16,MATCH($B29,'Inputs (detail)'!$B$10:$B$16,0)),'Travel Matrix'!$C$7:$C$205,0),MATCH(INDEX('Inputs (detail)'!$E$10:$E$16,MATCH(F$28,'Inputs (detail)'!$B$10:$B$16,0)),'Travel Matrix'!$D$6:$GT$6,0))*IF(INDEX('Travel Matrix'!$D$7:$GT$205,MATCH(INDEX('Inputs (detail)'!$E$10:$E$16,MATCH($B29,'Inputs (detail)'!$B$10:$B$16,0)),'Travel Matrix'!$C$7:$C$205,0),MATCH(INDEX('Inputs (detail)'!$E$10:$E$16,MATCH(F$28,'Inputs (detail)'!$B$10:$B$16,0)),'Travel Matrix'!$D$6:$GT$6,0))>Assumptions!$E$37,IF(F$27="Plane (Economy)",Assumptions!$E$35,Assumptions!$E$36),IF(F$9="Plane (Economy)",Assumptions!$E$33,Assumptions!$E$34))) -> 114.88066 | G29: =IF($B29=G$28,0,INDEX('Travel Matrix'!$D$7:$GT$205,MATCH(INDEX('Inputs (detail)'!$E$10:$E$16,MATCH($B29,'Inputs (detail)'!$B$10:$B$16,0)),'Travel Matrix'!$C$7:$C$205,0),MATCH(INDEX('Inputs (detail)'!$E$10:$E$16,MATCH(G$28,'Inputs (detail)'!$B$10:$B$16,0)),'Travel Matrix'!$D$6:$GT$6,0))*IF(INDEX('Travel Matrix'!$D$7:$GT$205,MATCH(INDEX('Inputs (detail)'!$E$10:$E$16,MATCH($B29,'Inputs (detail)'!$B$10:$B$16,0)),'Travel Matrix'!$C$7:$C$205,0),MATCH(INDEX('Inputs (detail)'!$E$10:$E$16,MATCH(G$28,'Inputs (detail)'!$B$10:$B$16,0)),'Travel Matrix'!$D$6:$GT$6,0))>Assumptions!$E$37,IF(G$27="Plane (Economy)",Assumptions!$E$35,Assumptions!$E$36),IF(G$9="Plane (Economy)",Assumptions!$E$33,Assumptions!$E$34))) -> 0 | H29: =IF($B29=H$28,0,INDEX('Travel Matrix'!$D$7:$GT$205,MATCH(INDEX('Inputs (detail)'!$E$10:$E$16,MATCH($B29,'Inputs (detail)'!$B$10:$B$16,0)),'Travel Matrix'!$C$7:$C$205,0),MATCH(INDEX('Inputs (detail)'!$E$10:$E$16,MATCH(H$28,'Inputs (detail)'!$B$10:$B$16,0)),'Travel Matrix'!$D$6:$GT$6,0))*IF(INDEX('Travel Matrix'!$D$7:$GT$205,MATCH(INDEX('Inputs (detail)'!$E$10:$E$16,MATCH($B29,'Inputs (detail)'!$B$10:$B$16,0)),'Travel Matrix'!$C$7:$C$205,0),MATCH(INDEX('Inputs (detail)'!$E$10:$E$16,MATCH(H$28,'Inputs (detail)'!$B$10:$B$16,0)),'Travel Matrix'!$D$6:$GT$6,0))>Assumptions!$E$37,IF(H$27="Plane (Economy)",Assumptions!$E$35,Assumptions!$E$36),IF(H$9="Plane (Economy)",Assumptions!$E$33,Assumptions!$E$34))) -> 142.11011 | I29: =IF($B29=I$28,0,INDEX('Travel Matrix'!$D$7:$GT$205,MATCH(INDEX('Inputs (detail)'!$E$10:$E$16,MATCH($B29,'Inputs (detail)'!$B$10:$B$16,0)),'Travel Matrix'!$C$7:$C$205,0),MATCH(INDEX('Inputs (detail)'!$E$10:$E$16,MATCH(I$28,'Inputs (detail)'!$B$10:$B$16,0)),'Travel Matrix'!$D$6:$GT$6,0))*IF(INDEX('Travel Matrix'!$D$7:$GT$205,MATCH(INDEX('Inputs (detail)'!$E$10:$E$16,MATCH($B29,'Inputs (detail)'!$B$10:$B$16,0)),'Travel Matrix'!$C$7:$C$205,0),MATCH(INDEX('Inputs (detail)'!$E$10:$E$16,MATCH(I$28,'Inputs (detail)'!$B$10:$B$16,0)),'Travel Matrix'!$D$6:$GT$6,0))>Assumptions!$E$37,IF(I$27="Plane (Economy)",Assumptions!$E$35,Assumptions!$E$36),IF(I$9="Plane (Economy)",Assumptions!$E$33,Assumptions!$E$34))) -> 259.11841 | J29: =IF($B29=J$28,0,INDEX('Travel Matrix'!$D$7:$GT$205,MATCH(INDEX('Inputs (detail)'!$E$10:$E$16,MATCH($B29,'Inputs (detail)'!$B$10:$B$16,0)),'Travel Matrix'!$C$7:$C$205,0),MATCH(INDEX('Inputs (detail)'!$E$10:$E$16,MATCH(J$28,'Inputs (detail)'!$B$10:$B$16,0)),'Travel Matrix'!$D$6:$GT$6,0))*IF(INDEX('Travel Matrix'!$D$7:$GT$205,MATCH(INDEX('Inputs (detail)'!$E$10:$E$16,MATCH($B29,'Inputs (detail)'!$B$10:$B$16,0)),'Travel Matrix'!$C$7:$C$205,0),MATCH(INDEX('Inputs (detail)'!$E$10:$E$16,MATCH(J$28,'Inputs (detail)'!$B$10:$B$16,0)),'Travel Matrix'!$D$6:$GT$6,0))>Assumptions!$E$37,IF(J$27="Plane (Economy)",Assumptions!$E$35,Assumptions!$E$36),IF(J$9="Plane (Economy)",Assumptions!$E$33,Assumptions!$E$34))) -> 172.32027 | K29: =IF($B29=K$28,0,INDEX('Travel Matrix'!$D$7:$GT$205,MATCH(INDEX('Inputs (detail)'!$E$10:$E$16,MATCH($B29,'Inputs (detail)'!$B$10:$B$16,0)),'Travel Matrix'!$C$7:$C$205,0),MATCH(INDEX('Inputs (detail)'!$E$10:$E$16,MATCH(K$28,'Inputs (detail)'!$B$10:$B$16,0)),'Travel Matrix'!$D$6:$GT$6,0)))*Assumptions!$E$38 -> 0 | L29: =IF($B29=L$28,0,INDEX('Travel Matrix'!$D$7:$GT$205,MATCH(INDEX('Inputs (detail)'!$E$10:$E$16,MATCH($B29,'Inputs (detail)'!$B$10:$B$16,0)),'Travel Matrix'!$C$7:$C$205,0),MATCH(INDEX('Inputs (detail)'!$E$10:$E$16,MATCH(L$28,'Inputs (detail)'!$B$10:$B$16,0)),'Travel Matrix'!$D$6:$GT$6,0)))*Assumptions!$E$38 -> 10.341353 | M29: =IF($B29=M$28,0,INDEX('Travel Matrix'!$D$7:$GT$205,MATCH(INDEX('Inputs (detail)'!$E$10:$E$16,MATCH($B29,'Inputs (detail)'!$B$10:$B$16,0)),'Travel Matrix'!$C$7:$C$205,0),MATCH(INDEX('Inputs (detail)'!$E$10:$E$16,MATCH(M$28,'Inputs (detail)'!$B$10:$B$16,0)),'Travel Matrix'!$D$6:$GT$6,0)))*Assumptions!$E$38 -> 18.856047 | N29: =IF($B29=N$28,0,INDEX('Travel Matrix'!$D$7:$GT$205,MATCH(INDEX('Inputs (detail)'!$E$10:$E$16,MATCH($B29,'Inputs (detail)'!$B$10:$B$16,0)),'Travel Matrix'!$C$7:$C$205,0),MATCH(INDEX('Inputs (detail)'!$E$10:$E$16,MATCH(N$28,'Inputs (detail)'!$B$10:$B$16,0)),'Travel Matrix'!$D$6:$GT$6,0)))*Assumptions!$E$38 -> 12.539746 | O29: =IF($B29=O$28,0,INDEX('Travel Matrix'!$D$7:$GT$205,MATCH(INDEX('Inputs (detail)'!$E$10:$E$16,MATCH($B29,'Inputs (detail)'!$B$10:$B$16,0)),'Travel Matrix'!$C$7:$C$205,0),MATCH(INDEX('Inputs (detail)'!$E$10:$E$16,MATCH(O$28,'Inputs (detail)'!$B$10:$B$16,0)),'Travel Matrix'!$D$6:$GT$6,0)))*Assumptions!$E$31 -> 0 | P29: =IF($B29=P$28,0,INDEX('Travel Matrix'!$D$7:$GT$205,MATCH(INDEX('Inputs (detail)'!$E$10:$E$16,MATCH($B29,'Inputs (detail)'!$B$10:$B$16,0)),'Travel Matrix'!$C$7:$C$205,0),MATCH(INDEX('Inputs (detail)'!$E$10:$E$16,MATCH(P$28,'Inputs (detail)'!$B$10:$B$16,0)),'Travel Matrix'!$D$6:$GT$6,0)))*Assumptions!$E$31 -> 78.180219 | Q29: =IF($B29=Q$28,0,INDEX('Travel Matrix'!$D$7:$GT$205,MATCH(INDEX('Inputs (detail)'!$E$10:$E$16,MATCH($B29,'Inputs (detail)'!$B$10:$B$16,0)),'Travel Matrix'!$C$7:$C$205,0),MATCH(INDEX('Inputs (detail)'!$E$10:$E$16,MATCH(Q$28,'Inputs (detail)'!$B$10:$B$16,0)),'Travel Matrix'!$D$6:$GT$6,0)))*Assumptions!$E$31 -> 142.55096 | R29: =IF($B29=R$28,0,INDEX('Travel Matrix'!$D$7:$GT$205,MATCH(INDEX('Inputs (detail)'!$E$10:$E$16,MATCH($B29,'Inputs (detail)'!$B$10:$B$16,0)),'Travel Matrix'!$C$7:$C$205,0),MATCH(INDEX('Inputs (detail)'!$E$10:$E$16,MATCH(R$28,'Inputs (detail)'!$B$10:$B$16,0)),'Travel Matrix'!$D$6:$GT$6,0)))*Assumptions!$E$31 -> 94.799983 | S29: =IF($B29=S$28,0,INDEX('Travel Matrix'!$D$7:$GT$205,MATCH(INDEX('Inputs (detail)'!$E$10:$E$16,MATCH($B29,'Inputs (detail)'!$B$10:$B$16,0)),'Travel Matrix'!$C$7:$C$205,0),MATCH(INDEX('Inputs (detail)'!$E$10:$E$16,MATCH(S$28,'Inputs (detail)'!$B$10:$B$16,0)),'Travel Matrix'!$D$6:$GT$6,0)))*Assumptions!$E$32 -> 0 | T29: =IF($B29=T$28,0,INDEX('Travel Matrix'!$D$7:$GT$205,MATCH(INDEX('Inputs (detail)'!$E$10:$E$16,MATCH($B29,'Inputs (detail)'!$B$10:$B$16,0)),'Travel Matrix'!$C$7:$C$205,0),MATCH(INDEX('Inputs (detail)'!$E$10:$E$16,MATCH(T$28,'Inputs (detail)'!$B$10:$B$16,0)),'Travel Matrix'!$D$6:$GT$6,0)))*Assumptions!$E$32 -> 28.388796 | U29: =IF($B29=U$28,0,INDEX('Travel Matrix'!$D$7:$GT$205,MATCH(INDEX('Inputs (detail)'!$E$10:$E$16,MATCH($B29,'Inputs (detail)'!$B$10:$B$16,0)),'Travel Matrix'!$C$7:$C$205,0),MATCH(INDEX('Inputs (detail)'!$E$10:$E$16,MATCH(U$28,'Inputs (detail)'!$B$10:$B$16,0)),'Travel Matrix'!$D$6:$GT$6,0)))*Assumptions!$E$32 -> 51.763098 | V29: =IF($B29=V$28,0,INDEX('Travel Matrix'!$D$7:$GT$205,MATCH(INDEX('Inputs (detail)'!$E$10:$E$16,MATCH($B29,'Inputs (detail)'!$B$10:$B$16,0)),'Travel Matrix'!$C$7:$C$205,0),MATCH(INDEX('Inputs (detail)'!$E$10:$E$16,MATCH(V$28,'Inputs (detail)'!$B$10:$B$16,0)),'Travel Matrix'!$D$6:$GT$6,0)))*Assumptions!$E$32 -> 34.423764
